<?xml version="1.0" encoding="UTF-8"?>
<!-- Generated by org.testng.reporters.JUnitReportReporter -->
<testsuite hostname="LT-jiangxm" name="com.llwallet.interfaces.test.api.test.personal.UserRefund1Test" tests="3" failures="2" timestamp="2 Nov 2017 13:27:28 GMT" time="1.909" errors="0">
  <testcase name="userRefund" time="1.884" classname="com.llwallet.interfaces.test.api.test.personal.UserRefund1Test"/>
  <testcase name="userRefund1" time="0.020" classname="com.llwallet.interfaces.test.api.test.personal.UserRefund1Test">
    <failure type="java.lang.NullPointerException">
      <![CDATA[java.lang.NullPointerException
	at com.tools.dataprovider.ExcelProvider.next(ExcelProvider.java:218)
	at com.tools.dataprovider.ExcelProvider.next(ExcelProvider.java:1)
	at org.testng.internal.Invoker.invokeTestMethods(Invoker.java:1183)
	at org.testng.internal.TestMethodWorker.invokeTestMethods(TestMethodWorker.java:124)
	at org.testng.internal.TestMethodWorker.run(TestMethodWorker.java:108)
	at org.testng.TestRunner.privateRun(TestRunner.java:767)
	at org.testng.TestRunner.run(TestRunner.java:617)
	at org.testng.SuiteRunner.runTest(SuiteRunner.java:348)
	at org.testng.SuiteRunner.runSequentially(SuiteRunner.java:343)
	at org.testng.SuiteRunner.privateRun(SuiteRunner.java:305)
	at org.testng.SuiteRunner.run(SuiteRunner.java:254)
	at org.testng.SuiteRunnerWorker.runSuite(SuiteRunnerWorker.java:52)
	at org.testng.SuiteRunnerWorker.run(SuiteRunnerWorker.java:86)
	at org.testng.TestNG.runSuitesSequentially(TestNG.java:1224)
	at org.testng.TestNG.runSuitesLocally(TestNG.java:1149)
	at org.testng.TestNG.run(TestNG.java:1057)
	at org.testng.remote.RemoteTestNG.run(RemoteTestNG.java:111)
	at org.testng.remote.RemoteTestNG.initAndRun(RemoteTestNG.java:204)
	at org.testng.remote.RemoteTestNG.main(RemoteTestNG.java:175)
]]>
    </failure>
  </testcase> <!-- userRefund1 -->
  <testcase name="userRefund2" time="0.005" classname="com.llwallet.interfaces.test.api.test.personal.UserRefund1Test">
    <failure type="java.lang.NullPointerException">
      <![CDATA[java.lang.NullPointerException
	at com.tools.dataprovider.ExcelProvider.next(ExcelProvider.java:218)
	at com.tools.dataprovider.ExcelProvider.next(ExcelProvider.java:1)
	at org.testng.internal.Invoker.invokeTestMethods(Invoker.java:1183)
	at org.testng.internal.TestMethodWorker.invokeTestMethods(TestMethodWorker.java:124)
	at org.testng.internal.TestMethodWorker.run(TestMethodWorker.java:108)
	at org.testng.TestRunner.privateRun(TestRunner.java:767)
	at org.testng.TestRunner.run(TestRunner.java:617)
	at org.testng.SuiteRunner.runTest(SuiteRunner.java:348)
	at org.testng.SuiteRunner.runSequentially(SuiteRunner.java:343)
	at org.testng.SuiteRunner.privateRun(SuiteRunner.java:305)
	at org.testng.SuiteRunner.run(SuiteRunner.java:254)
	at org.testng.SuiteRunnerWorker.runSuite(SuiteRunnerWorker.java:52)
	at org.testng.SuiteRunnerWorker.run(SuiteRunnerWorker.java:86)
	at org.testng.TestNG.runSuitesSequentially(TestNG.java:1224)
	at org.testng.TestNG.runSuitesLocally(TestNG.java:1149)
	at org.testng.TestNG.run(TestNG.java:1057)
	at org.testng.remote.RemoteTestNG.run(RemoteTestNG.java:111)
	at org.testng.remote.RemoteTestNG.initAndRun(RemoteTestNG.java:204)
	at org.testng.remote.RemoteTestNG.main(RemoteTestNG.java:175)
]]>
    </failure>
  </testcase> <!-- userRefund2 -->
</testsuite> <!-- com.llwallet.interfaces.test.api.test.personal.UserRefund1Test -->
