<?xml version="1.0" encoding="UTF-8"?>
<!-- Generated by org.testng.reporters.JUnitReportReporter -->
<testsuite hostname="LT-jiangxm" name="com.llwallet.interfaces.test.api.test.personal.UserAuthQueryTest" tests="4" failures="0" timestamp="2 Nov 2017 13:27:28 GMT" time="1.141" errors="1">
  <testcase name="userAuthQuery" time="0.279" classname="com.llwallet.interfaces.test.api.test.personal.UserAuthQueryTest"/>
  <testcase name="userAuthQuery" time="0.481" classname="com.llwallet.interfaces.test.api.test.personal.UserAuthQueryTest"/>
  <testcase name="userAuthQuery" time="0.096" classname="com.llwallet.interfaces.test.api.test.personal.UserAuthQueryTest">
    <error type="java.lang.AssertionError">
      <![CDATA[java.lang.AssertionError
	at com.llwallet.interfaces.test.api.test.personal.UserAuthQueryTest.userAuthQuery(UserAuthQueryTest.java:49)
	at sun.reflect.NativeMethodAccessorImpl.invoke0(Native Method)
	at sun.reflect.NativeMethodAccessorImpl.invoke(Unknown Source)
	at sun.reflect.DelegatingMethodAccessorImpl.invoke(Unknown Source)
	at java.lang.reflect.Method.invoke(Unknown Source)
	at org.testng.internal.MethodInvocationHelper.invokeMethod(MethodInvocationHelper.java:85)
	at org.testng.internal.InvokeMethodRunnable.runOne(InvokeMethodRunnable.java:46)
	at org.testng.internal.InvokeMethodRunnable.run(InvokeMethodRunnable.java:37)
	at java.util.concurrent.Executors$RunnableAdapter.call(Unknown Source)
	at java.util.concurrent.FutureTask.run(Unknown Source)
	at java.util.concurrent.ThreadPoolExecutor.runWorker(Unknown Source)
	at java.util.concurrent.ThreadPoolExecutor$Worker.run(Unknown Source)
	at java.lang.Thread.run(Unknown Source)
]]>
    </error>
  </testcase> <!-- userAuthQuery -->
  <testcase name="userAuthQuery" time="0.285" classname="com.llwallet.interfaces.test.api.test.personal.UserAuthQueryTest"/>
</testsuite> <!-- com.llwallet.interfaces.test.api.test.personal.UserAuthQueryTest -->
